[2023-03-30 04:57:17,763] {taskinstance.py:903} INFO - Dependencies all met for <TaskInstance: inovus_etl_odb_to_mrr.etl_odb_to_mrr_f_sales 2023-03-28T00:00:00+00:00 [queued]>
[2023-03-30 04:57:17,812] {taskinstance.py:903} INFO - Dependencies all met for <TaskInstance: inovus_etl_odb_to_mrr.etl_odb_to_mrr_f_sales 2023-03-28T00:00:00+00:00 [queued]>
[2023-03-30 04:57:17,814] {taskinstance.py:1095} INFO - 
--------------------------------------------------------------------------------
[2023-03-30 04:57:17,817] {taskinstance.py:1096} INFO - Starting attempt 1 of 1
[2023-03-30 04:57:17,821] {taskinstance.py:1097} INFO - 
--------------------------------------------------------------------------------
[2023-03-30 04:57:17,871] {taskinstance.py:1115} INFO - Executing <Task(PythonOperator): etl_odb_to_mrr_f_sales> on 2023-03-28T00:00:00+00:00
[2023-03-30 04:57:17,905] {standard_task_runner.py:76} INFO - Running: ['***', 'tasks', 'run', 'inovus_etl_odb_to_mrr', 'etl_odb_to_mrr_f_sales', '2023-03-28T00:00:00+00:00', '--job-id', '467', '--pool', 'default_pool', '--raw', '--subdir', 'DAGS_FOLDER/inovus_etl_odb_mrr1.py', '--cfg-path', '/tmp/tmpr_1py5cs', '--error-file', '/tmp/tmpblobrcjn']
[2023-03-30 04:57:17,909] {standard_task_runner.py:77} INFO - Job 467: Subtask etl_odb_to_mrr_f_sales
[2023-03-30 04:57:17,882] {standard_task_runner.py:52} INFO - Started process 7495 to run task
[2023-03-30 04:57:18,391] {logging_mixin.py:109} INFO - Running <TaskInstance: inovus_etl_odb_to_mrr.etl_odb_to_mrr_f_sales 2023-03-28T00:00:00+00:00 [running]> on host 0bc3da97cebb
[2023-03-30 04:57:18,594] {taskinstance.py:1254} INFO - Exporting the following env vars:
AIRFLOW_CTX_DAG_OWNER=***
AIRFLOW_CTX_DAG_ID=inovus_etl_odb_to_mrr
AIRFLOW_CTX_TASK_ID=etl_odb_to_mrr_f_sales
AIRFLOW_CTX_EXECUTION_DATE=2023-03-28T00:00:00+00:00
AIRFLOW_CTX_DAG_RUN_ID=scheduled__2023-03-28T00:00:00+00:00
[2023-03-30 04:57:18,879] {taskinstance.py:1463} ERROR - Task failed with exception
Traceback (most recent call last):
  File "/opt/airflow/dags/inovus_etl_odb_mrr1.py", line 60, in etl_to_mmr_f_sale
    create_log_suc('etl_to_mmr_f_sale')
  File "/opt/airflow/dags/inovus_etl_odb_mrr1.py", line 40, in create_log_suc
    cur.execute('insert into logs.etl_logs (event_time, event_name, event_type) VALUES (%s, %s, %s)', (time.asctime(), 'INFO', f'{name} - task finished'))
psycopg2.errors.UndefinedColumn: column "event_name" of relation "etl_logs" does not exist
LINE 1: insert into logs.etl_logs (event_time, event_name, event_typ...
                                               ^


During handling of the above exception, another exception occurred:

Traceback (most recent call last):
  File "/home/airflow/.local/lib/python3.6/site-packages/airflow/models/taskinstance.py", line 1165, in _run_raw_task
    self._prepare_and_execute_task_with_callbacks(context, task)
  File "/home/airflow/.local/lib/python3.6/site-packages/airflow/models/taskinstance.py", line 1283, in _prepare_and_execute_task_with_callbacks
    result = self._execute_task(context, task_copy)
  File "/home/airflow/.local/lib/python3.6/site-packages/airflow/models/taskinstance.py", line 1313, in _execute_task
    result = task_copy.execute(context=context)
  File "/home/airflow/.local/lib/python3.6/site-packages/airflow/operators/python.py", line 150, in execute
    return_value = self.execute_callable()
  File "/home/airflow/.local/lib/python3.6/site-packages/airflow/operators/python.py", line 161, in execute_callable
    return self.python_callable(*self.op_args, **self.op_kwargs)
  File "/opt/airflow/dags/inovus_etl_odb_mrr1.py", line 62, in etl_to_mmr_f_sale
    create_log_er('etl_to_mmr_f_sale')
  File "/opt/airflow/dags/inovus_etl_odb_mrr1.py", line 47, in create_log_er
    cur.execute('insert into logs.etl_logs (event_time, event_name, event_type) VALUES (%s, %s, %s)', (time.asctime(), 'ERROR', f'{name} - task failed'))
psycopg2.errors.UndefinedColumn: column "event_name" of relation "etl_logs" does not exist
LINE 1: insert into logs.etl_logs (event_time, event_name, event_typ...
                                               ^

[2023-03-30 04:57:18,909] {taskinstance.py:1513} INFO - Marking task as FAILED. dag_id=inovus_etl_odb_to_mrr, task_id=etl_odb_to_mrr_f_sales, execution_date=20230328T000000, start_date=20230330T045717, end_date=20230330T045718
[2023-03-30 04:57:18,997] {local_task_job.py:151} INFO - Task exited with return code 1
[2023-03-30 04:57:19,084] {local_task_job.py:261} INFO - 0 downstream tasks scheduled from follow-on schedule check
