[2023-03-29 16:08:25,930] {taskinstance.py:903} INFO - Dependencies all met for <TaskInstance: postgres_22222222222.log_error 2023-03-29T16:08:24.404959+00:00 [queued]>
[2023-03-29 16:08:25,948] {taskinstance.py:903} INFO - Dependencies all met for <TaskInstance: postgres_22222222222.log_error 2023-03-29T16:08:24.404959+00:00 [queued]>
[2023-03-29 16:08:25,950] {taskinstance.py:1095} INFO - 
--------------------------------------------------------------------------------
[2023-03-29 16:08:25,952] {taskinstance.py:1096} INFO - Starting attempt 1 of 1
[2023-03-29 16:08:25,954] {taskinstance.py:1097} INFO - 
--------------------------------------------------------------------------------
[2023-03-29 16:08:25,997] {taskinstance.py:1115} INFO - Executing <Task(PythonOperator): log_error> on 2023-03-29T16:08:24.404959+00:00
[2023-03-29 16:08:26,006] {standard_task_runner.py:52} INFO - Started process 25894 to run task
[2023-03-29 16:08:26,020] {standard_task_runner.py:76} INFO - Running: ['***', 'tasks', 'run', 'postgres_22222222222', 'log_error', '2023-03-29T16:08:24.404959+00:00', '--job-id', '273', '--pool', 'default_pool', '--raw', '--subdir', 'DAGS_FOLDER/ETL.py', '--cfg-path', '/tmp/tmpv92mpvzq', '--error-file', '/tmp/tmptcd1arh8']
[2023-03-29 16:08:26,022] {standard_task_runner.py:77} INFO - Job 273: Subtask log_error
[2023-03-29 16:08:26,102] {logging_mixin.py:109} INFO - Running <TaskInstance: postgres_22222222222.log_error 2023-03-29T16:08:24.404959+00:00 [running]> on host 0bc3da97cebb
[2023-03-29 16:08:26,172] {taskinstance.py:1254} INFO - Exporting the following env vars:
AIRFLOW_CTX_DAG_OWNER=***
AIRFLOW_CTX_DAG_ID=postgres_22222222222
AIRFLOW_CTX_TASK_ID=log_error
AIRFLOW_CTX_EXECUTION_DATE=2023-03-29T16:08:24.404959+00:00
AIRFLOW_CTX_DAG_RUN_ID=manual__2023-03-29T16:08:24.404959+00:00
[2023-03-29 16:08:26,175] {ETL.py:67} ERROR - task is NOT completed
[2023-03-29 16:08:26,178] {taskinstance.py:1463} ERROR - Task failed with exception
Traceback (most recent call last):
  File "/home/airflow/.local/lib/python3.6/site-packages/airflow/models/taskinstance.py", line 1165, in _run_raw_task
    self._prepare_and_execute_task_with_callbacks(context, task)
  File "/home/airflow/.local/lib/python3.6/site-packages/airflow/models/taskinstance.py", line 1283, in _prepare_and_execute_task_with_callbacks
    result = self._execute_task(context, task_copy)
  File "/home/airflow/.local/lib/python3.6/site-packages/airflow/models/taskinstance.py", line 1313, in _execute_task
    result = task_copy.execute(context=context)
  File "/home/airflow/.local/lib/python3.6/site-packages/airflow/operators/python.py", line 150, in execute
    return_value = self.execute_callable()
  File "/home/airflow/.local/lib/python3.6/site-packages/airflow/operators/python.py", line 161, in execute_callable
    return self.python_callable(*self.op_args, **self.op_kwargs)
  File "/opt/airflow/dags/ETL.py", line 72, in creatte_log_er
    conn_log = get_log_connection()
  File "/opt/airflow/dags/ETL.py", line 19, in get_log_connection
    port="5434"
  File "/home/airflow/.local/lib/python3.6/site-packages/psycopg2/__init__.py", line 122, in connect
    conn = _connect(dsn, connection_factory=connection_factory, **kwasync)
psycopg2.OperationalError: could not connect to server: Connection refused
	Is the server running on host "localhost" (127.0.0.1) and accepting
	TCP/IP connections on port 5434?
could not connect to server: Cannot assign requested address
	Is the server running on host "localhost" (::1) and accepting
	TCP/IP connections on port 5434?

[2023-03-29 16:08:26,187] {taskinstance.py:1513} INFO - Marking task as FAILED. dag_id=postgres_22222222222, task_id=log_error, execution_date=20230329T160824, start_date=20230329T160825, end_date=20230329T160826
[2023-03-29 16:08:26,239] {local_task_job.py:151} INFO - Task exited with return code 1
[2023-03-29 16:08:26,267] {local_task_job.py:261} INFO - 0 downstream tasks scheduled from follow-on schedule check
