[2023-03-29 16:39:52,182] {taskinstance.py:903} INFO - Dependencies all met for <TaskInstance: postgres_22222222222.log_suc 2023-03-29T16:39:45.898393+00:00 [queued]>
[2023-03-29 16:39:52,195] {taskinstance.py:903} INFO - Dependencies all met for <TaskInstance: postgres_22222222222.log_suc 2023-03-29T16:39:45.898393+00:00 [queued]>
[2023-03-29 16:39:52,196] {taskinstance.py:1095} INFO - 
--------------------------------------------------------------------------------
[2023-03-29 16:39:52,198] {taskinstance.py:1096} INFO - Starting attempt 1 of 1
[2023-03-29 16:39:52,199] {taskinstance.py:1097} INFO - 
--------------------------------------------------------------------------------
[2023-03-29 16:39:52,216] {taskinstance.py:1115} INFO - Executing <Task(PythonOperator): log_suc> on 2023-03-29T16:39:45.898393+00:00
[2023-03-29 16:39:52,222] {standard_task_runner.py:52} INFO - Started process 27606 to run task
[2023-03-29 16:39:52,229] {standard_task_runner.py:76} INFO - Running: ['***', 'tasks', 'run', 'postgres_22222222222', 'log_suc', '2023-03-29T16:39:45.898393+00:00', '--job-id', '409', '--pool', 'default_pool', '--raw', '--subdir', 'DAGS_FOLDER/ETL.py', '--cfg-path', '/tmp/tmplb76fm9p', '--error-file', '/tmp/tmpf_fqabkn']
[2023-03-29 16:39:52,231] {standard_task_runner.py:77} INFO - Job 409: Subtask log_suc
[2023-03-29 16:39:52,285] {logging_mixin.py:109} INFO - Running <TaskInstance: postgres_22222222222.log_suc 2023-03-29T16:39:45.898393+00:00 [running]> on host 0bc3da97cebb
[2023-03-29 16:39:52,342] {taskinstance.py:1254} INFO - Exporting the following env vars:
AIRFLOW_CTX_DAG_OWNER=***
AIRFLOW_CTX_DAG_ID=postgres_22222222222
AIRFLOW_CTX_TASK_ID=log_suc
AIRFLOW_CTX_EXECUTION_DATE=2023-03-29T16:39:45.898393+00:00
AIRFLOW_CTX_DAG_RUN_ID=manual__2023-03-29T16:39:45.898393+00:00
[2023-03-29 16:39:52,347] {ETL.py:54} INFO - completed
[2023-03-29 16:39:52,372] {taskinstance.py:1463} ERROR - Task failed with exception
Traceback (most recent call last):
  File "/home/airflow/.local/lib/python3.6/site-packages/airflow/models/taskinstance.py", line 1165, in _run_raw_task
    self._prepare_and_execute_task_with_callbacks(context, task)
  File "/home/airflow/.local/lib/python3.6/site-packages/airflow/models/taskinstance.py", line 1283, in _prepare_and_execute_task_with_callbacks
    result = self._execute_task(context, task_copy)
  File "/home/airflow/.local/lib/python3.6/site-packages/airflow/models/taskinstance.py", line 1313, in _execute_task
    result = task_copy.execute(context=context)
  File "/home/airflow/.local/lib/python3.6/site-packages/airflow/operators/python.py", line 150, in execute
    return_value = self.execute_callable()
  File "/home/airflow/.local/lib/python3.6/site-packages/airflow/operators/python.py", line 161, in execute_callable
    return self.python_callable(*self.op_args, **self.op_kwargs)
  File "/opt/airflow/dags/ETL.py", line 61, in creatte_log_suc
    cur.execute('insert into logs.etl_logs (event_time, event_name, event_type) VALUES (%s, %s, %s)', (mes[1], 'value2', 'value3'))
IndexError: string index out of range
[2023-03-29 16:39:52,389] {taskinstance.py:1513} INFO - Marking task as FAILED. dag_id=postgres_22222222222, task_id=log_suc, execution_date=20230329T163945, start_date=20230329T163952, end_date=20230329T163952
[2023-03-29 16:39:52,448] {local_task_job.py:151} INFO - Task exited with return code 1
[2023-03-29 16:39:52,479] {local_task_job.py:261} INFO - 0 downstream tasks scheduled from follow-on schedule check
