[2023-03-28 18:21:14,491] {taskinstance.py:903} INFO - Dependencies all met for <TaskInstance: inovus_etl_dag_mrr_to_stg.etl_from_mrrdimcustomer_to_stgdimcustomer 2023-03-27T00:00:00+00:00 [queued]>
[2023-03-28 18:21:14,576] {taskinstance.py:903} INFO - Dependencies all met for <TaskInstance: inovus_etl_dag_mrr_to_stg.etl_from_mrrdimcustomer_to_stgdimcustomer 2023-03-27T00:00:00+00:00 [queued]>
[2023-03-28 18:21:14,578] {taskinstance.py:1095} INFO - 
--------------------------------------------------------------------------------
[2023-03-28 18:21:14,580] {taskinstance.py:1096} INFO - Starting attempt 1 of 1
[2023-03-28 18:21:14,581] {taskinstance.py:1097} INFO - 
--------------------------------------------------------------------------------
[2023-03-28 18:21:14,699] {taskinstance.py:1115} INFO - Executing <Task(PythonOperator): etl_from_mrrdimcustomer_to_stgdimcustomer> on 2023-03-27T00:00:00+00:00
[2023-03-28 18:21:14,784] {standard_task_runner.py:76} INFO - Running: ['***', 'tasks', 'run', 'inovus_etl_dag_mrr_to_stg', 'etl_from_mrrdimcustomer_to_stgdimcustomer', '2023-03-27T00:00:00+00:00', '--job-id', '42', '--pool', 'default_pool', '--raw', '--subdir', 'DAGS_FOLDER/inovus_etl_mrr_stg.py', '--cfg-path', '/tmp/tmpxg7wdppo', '--error-file', '/tmp/tmp0lfl0u84']
[2023-03-28 18:21:14,751] {standard_task_runner.py:52} INFO - Started process 8395 to run task
[2023-03-28 18:21:14,878] {standard_task_runner.py:77} INFO - Job 42: Subtask etl_from_mrrdimcustomer_to_stgdimcustomer
[2023-03-28 18:21:15,176] {logging_mixin.py:109} INFO - Running <TaskInstance: inovus_etl_dag_mrr_to_stg.etl_from_mrrdimcustomer_to_stgdimcustomer 2023-03-27T00:00:00+00:00 [running]> on host 0bc3da97cebb
[2023-03-28 18:21:15,459] {taskinstance.py:1254} INFO - Exporting the following env vars:
AIRFLOW_CTX_DAG_OWNER=***
AIRFLOW_CTX_DAG_ID=inovus_etl_dag_mrr_to_stg
AIRFLOW_CTX_TASK_ID=etl_from_mrrdimcustomer_to_stgdimcustomer
AIRFLOW_CTX_EXECUTION_DATE=2023-03-27T00:00:00+00:00
AIRFLOW_CTX_DAG_RUN_ID=scheduled__2023-03-27T00:00:00+00:00
[2023-03-28 18:21:15,554] {taskinstance.py:1463} ERROR - Task failed with exception
Traceback (most recent call last):
  File "/home/airflow/.local/lib/python3.6/site-packages/airflow/models/taskinstance.py", line 1165, in _run_raw_task
    self._prepare_and_execute_task_with_callbacks(context, task)
  File "/home/airflow/.local/lib/python3.6/site-packages/airflow/models/taskinstance.py", line 1283, in _prepare_and_execute_task_with_callbacks
    result = self._execute_task(context, task_copy)
  File "/home/airflow/.local/lib/python3.6/site-packages/airflow/models/taskinstance.py", line 1313, in _execute_task
    result = task_copy.execute(context=context)
  File "/home/airflow/.local/lib/python3.6/site-packages/airflow/operators/python.py", line 150, in execute
    return_value = self.execute_callable()
  File "/home/airflow/.local/lib/python3.6/site-packages/airflow/operators/python.py", line 161, in execute_callable
    return self.python_callable(*self.op_args, **self.op_kwargs)
  File "/opt/airflow/dags/inovus_etl_mrr_stg.py", line 30, in etl_inovus_dimcustimer
    cur.execute("select * from mrr.dimension_custimer;") # 1
psycopg2.errors.UndefinedTable: relation "mrr.dimension_custimer" does not exist
LINE 1: select * from mrr.dimension_custimer;
                      ^

[2023-03-28 18:21:15,586] {taskinstance.py:1513} INFO - Marking task as FAILED. dag_id=inovus_etl_dag_mrr_to_stg, task_id=etl_from_mrrdimcustomer_to_stgdimcustomer, execution_date=20230327T000000, start_date=20230328T182114, end_date=20230328T182115
[2023-03-28 18:21:15,829] {local_task_job.py:151} INFO - Task exited with return code 1
[2023-03-28 18:21:16,155] {local_task_job.py:261} INFO - 0 downstream tasks scheduled from follow-on schedule check
