[2023-03-29 07:36:19,946] {taskinstance.py:903} INFO - Dependencies all met for <TaskInstance: postgres_etl_dag_radb_to_mrr.date_update_mrr 2023-03-29T07:36:16.639060+00:00 [queued]>
[2023-03-29 07:36:20,023] {taskinstance.py:903} INFO - Dependencies all met for <TaskInstance: postgres_etl_dag_radb_to_mrr.date_update_mrr 2023-03-29T07:36:16.639060+00:00 [queued]>
[2023-03-29 07:36:20,025] {taskinstance.py:1095} INFO - 
--------------------------------------------------------------------------------
[2023-03-29 07:36:20,027] {taskinstance.py:1096} INFO - Starting attempt 1 of 1
[2023-03-29 07:36:20,029] {taskinstance.py:1097} INFO - 
--------------------------------------------------------------------------------
[2023-03-29 07:36:20,076] {taskinstance.py:1115} INFO - Executing <Task(PythonOperator): date_update_mrr> on 2023-03-29T07:36:16.639060+00:00
[2023-03-29 07:36:20,102] {standard_task_runner.py:76} INFO - Running: ['***', 'tasks', 'run', 'postgres_etl_dag_radb_to_mrr', 'date_update_mrr', '2023-03-29T07:36:16.639060+00:00', '--job-id', '111', '--pool', 'default_pool', '--raw', '--subdir', 'DAGS_FOLDER/inovus_etl_radb_mrr.py', '--cfg-path', '/tmp/tmpp7f1l7it', '--error-file', '/tmp/tmptllpqfkm']
[2023-03-29 07:36:20,106] {standard_task_runner.py:77} INFO - Job 111: Subtask date_update_mrr
[2023-03-29 07:36:20,093] {standard_task_runner.py:52} INFO - Started process 2354 to run task
[2023-03-29 07:36:20,216] {logging_mixin.py:109} INFO - Running <TaskInstance: postgres_etl_dag_radb_to_mrr.date_update_mrr 2023-03-29T07:36:16.639060+00:00 [running]> on host 0bc3da97cebb
[2023-03-29 07:36:20,403] {taskinstance.py:1254} INFO - Exporting the following env vars:
AIRFLOW_CTX_DAG_OWNER=***
AIRFLOW_CTX_DAG_ID=postgres_etl_dag_radb_to_mrr
AIRFLOW_CTX_TASK_ID=date_update_mrr
AIRFLOW_CTX_EXECUTION_DATE=2023-03-29T07:36:16.639060+00:00
AIRFLOW_CTX_DAG_RUN_ID=manual__2023-03-29T07:36:16.639060+00:00
[2023-03-29 07:36:20,419] {taskinstance.py:1463} ERROR - Task failed with exception
Traceback (most recent call last):
  File "/home/airflow/.local/lib/python3.6/site-packages/airflow/models/taskinstance.py", line 1165, in _run_raw_task
    self._prepare_and_execute_task_with_callbacks(context, task)
  File "/home/airflow/.local/lib/python3.6/site-packages/airflow/models/taskinstance.py", line 1283, in _prepare_and_execute_task_with_callbacks
    result = self._execute_task(context, task_copy)
  File "/home/airflow/.local/lib/python3.6/site-packages/airflow/models/taskinstance.py", line 1313, in _execute_task
    result = task_copy.execute(context=context)
  File "/home/airflow/.local/lib/python3.6/site-packages/airflow/operators/python.py", line 150, in execute
    return_value = self.execute_callable()
  File "/home/airflow/.local/lib/python3.6/site-packages/airflow/operators/python.py", line 161, in execute_callable
    return self.python_callable(*self.op_args, **self.op_kwargs)
  File "/opt/airflow/dags/inovus_etl_radb_mrr.py", line 67, in update_high_water_mark
    cur_i = conn_inovus.cursor()
AttributeError: 'function' object has no attribute 'cursor'
[2023-03-29 07:36:20,485] {taskinstance.py:1513} INFO - Marking task as FAILED. dag_id=postgres_etl_dag_radb_to_mrr, task_id=date_update_mrr, execution_date=20230329T073616, start_date=20230329T073619, end_date=20230329T073620
[2023-03-29 07:36:20,659] {local_task_job.py:151} INFO - Task exited with return code 1
[2023-03-29 07:36:20,735] {local_task_job.py:261} INFO - 0 downstream tasks scheduled from follow-on schedule check
