[2023-03-28 18:46:11,776] {taskinstance.py:903} INFO - Dependencies all met for <TaskInstance: inovus_etl_dag_stg_to_dwh.etl_from_stgfsales_to_dwhfsales 2023-03-28T18:46:08.140238+00:00 [queued]>
[2023-03-28 18:46:11,799] {taskinstance.py:903} INFO - Dependencies all met for <TaskInstance: inovus_etl_dag_stg_to_dwh.etl_from_stgfsales_to_dwhfsales 2023-03-28T18:46:08.140238+00:00 [queued]>
[2023-03-28 18:46:11,811] {taskinstance.py:1095} INFO - 
--------------------------------------------------------------------------------
[2023-03-28 18:46:11,813] {taskinstance.py:1096} INFO - Starting attempt 1 of 1
[2023-03-28 18:46:11,814] {taskinstance.py:1097} INFO - 
--------------------------------------------------------------------------------
[2023-03-28 18:46:11,842] {taskinstance.py:1115} INFO - Executing <Task(PythonOperator): etl_from_stgfsales_to_dwhfsales> on 2023-03-28T18:46:08.140238+00:00
[2023-03-28 18:46:11,869] {standard_task_runner.py:76} INFO - Running: ['***', 'tasks', 'run', 'inovus_etl_dag_stg_to_dwh', 'etl_from_stgfsales_to_dwhfsales', '2023-03-28T18:46:08.140238+00:00', '--job-id', '90', '--pool', 'default_pool', '--raw', '--subdir', 'DAGS_FOLDER/inovus_etl_stg_dwh.py', '--cfg-path', '/tmp/tmp9yx4qox3', '--error-file', '/tmp/tmps7mlpsgx']
[2023-03-28 18:46:11,872] {standard_task_runner.py:77} INFO - Job 90: Subtask etl_from_stgfsales_to_dwhfsales
[2023-03-28 18:46:11,863] {standard_task_runner.py:52} INFO - Started process 9653 to run task
[2023-03-28 18:46:11,963] {logging_mixin.py:109} INFO - Running <TaskInstance: inovus_etl_dag_stg_to_dwh.etl_from_stgfsales_to_dwhfsales 2023-03-28T18:46:08.140238+00:00 [running]> on host 0bc3da97cebb
[2023-03-28 18:46:12,041] {taskinstance.py:1254} INFO - Exporting the following env vars:
AIRFLOW_CTX_DAG_OWNER=***
AIRFLOW_CTX_DAG_ID=inovus_etl_dag_stg_to_dwh
AIRFLOW_CTX_TASK_ID=etl_from_stgfsales_to_dwhfsales
AIRFLOW_CTX_EXECUTION_DATE=2023-03-28T18:46:08.140238+00:00
AIRFLOW_CTX_DAG_RUN_ID=manual__2023-03-28T18:46:08.140238+00:00
[2023-03-28 18:46:12,089] {taskinstance.py:1463} ERROR - Task failed with exception
Traceback (most recent call last):
  File "/home/airflow/.local/lib/python3.6/site-packages/airflow/models/taskinstance.py", line 1165, in _run_raw_task
    self._prepare_and_execute_task_with_callbacks(context, task)
  File "/home/airflow/.local/lib/python3.6/site-packages/airflow/models/taskinstance.py", line 1283, in _prepare_and_execute_task_with_callbacks
    result = self._execute_task(context, task_copy)
  File "/home/airflow/.local/lib/python3.6/site-packages/airflow/models/taskinstance.py", line 1313, in _execute_task
    result = task_copy.execute(context=context)
  File "/home/airflow/.local/lib/python3.6/site-packages/airflow/operators/python.py", line 150, in execute
    return_value = self.execute_callable()
  File "/home/airflow/.local/lib/python3.6/site-packages/airflow/operators/python.py", line 161, in execute_callable
    return self.python_callable(*self.op_args, **self.op_kwargs)
  File "/opt/airflow/dags/inovus_etl_stg_dwh.py", line 24, in etl_inovus_fsale
    cur.executemany('insert into dwh.fact_sales values (%s, %s, %s)', rows) # 2
psycopg2.errors.ForeignKeyViolation: insert or update on table "fact_sales" violates foreign key constraint "fk_1"
DETAIL:  Key (custumer_id)=(1) is not present in table "dimension_customer".

[2023-03-28 18:46:12,099] {taskinstance.py:1513} INFO - Marking task as FAILED. dag_id=inovus_etl_dag_stg_to_dwh, task_id=etl_from_stgfsales_to_dwhfsales, execution_date=20230328T184608, start_date=20230328T184611, end_date=20230328T184612
[2023-03-28 18:46:12,142] {local_task_job.py:151} INFO - Task exited with return code 1
[2023-03-28 18:46:12,187] {local_task_job.py:261} INFO - 0 downstream tasks scheduled from follow-on schedule check
