[2023-04-02 17:30:01,394] {taskinstance.py:903} INFO - Dependencies all met for <TaskInstance: inovus_etl_dag_stg_to_dwh.etl_from_stgfsales_to_dwhfsales 2023-04-02T17:29:57.741593+00:00 [queued]>
[2023-04-02 17:30:01,460] {taskinstance.py:903} INFO - Dependencies all met for <TaskInstance: inovus_etl_dag_stg_to_dwh.etl_from_stgfsales_to_dwhfsales 2023-04-02T17:29:57.741593+00:00 [queued]>
[2023-04-02 17:30:01,464] {taskinstance.py:1095} INFO - 
--------------------------------------------------------------------------------
[2023-04-02 17:30:01,466] {taskinstance.py:1096} INFO - Starting attempt 1 of 1
[2023-04-02 17:30:01,469] {taskinstance.py:1097} INFO - 
--------------------------------------------------------------------------------
[2023-04-02 17:30:01,513] {taskinstance.py:1115} INFO - Executing <Task(PythonOperator): etl_from_stgfsales_to_dwhfsales> on 2023-04-02T17:29:57.741593+00:00
[2023-04-02 17:30:01,529] {standard_task_runner.py:52} INFO - Started process 1029 to run task
[2023-04-02 17:30:01,541] {standard_task_runner.py:76} INFO - Running: ['***', 'tasks', 'run', 'inovus_etl_dag_stg_to_dwh', 'etl_from_stgfsales_to_dwhfsales', '2023-04-02T17:29:57.741593+00:00', '--job-id', '556', '--pool', 'default_pool', '--raw', '--subdir', 'DAGS_FOLDER/inovus_etl_stg_dwh.py', '--cfg-path', '/tmp/tmpbd9liq_u', '--error-file', '/tmp/tmp1u89yo_3']
[2023-04-02 17:30:01,543] {standard_task_runner.py:77} INFO - Job 556: Subtask etl_from_stgfsales_to_dwhfsales
[2023-04-02 17:30:01,624] {logging_mixin.py:109} INFO - Running <TaskInstance: inovus_etl_dag_stg_to_dwh.etl_from_stgfsales_to_dwhfsales 2023-04-02T17:29:57.741593+00:00 [running]> on host 580553a30a83
[2023-04-02 17:30:01,748] {taskinstance.py:1254} INFO - Exporting the following env vars:
AIRFLOW_CTX_DAG_OWNER=***
AIRFLOW_CTX_DAG_ID=inovus_etl_dag_stg_to_dwh
AIRFLOW_CTX_TASK_ID=etl_from_stgfsales_to_dwhfsales
AIRFLOW_CTX_EXECUTION_DATE=2023-04-02T17:29:57.741593+00:00
AIRFLOW_CTX_DAG_RUN_ID=manual__2023-04-02T17:29:57.741593+00:00
[2023-04-02 17:30:01,826] {taskinstance.py:1463} ERROR - Task failed with exception
Traceback (most recent call last):
  File "/opt/airflow/dags/inovus_etl_stg_dwh.py", line 47, in etl_inovus_dwh_f_sale
    cur.executemany('insert into dwh.fact_sales values (%s, %s, %s)', rows) # 2
psycopg2.errors.FunctionExecutedNoReturnStatement: control reached end of trigger procedure without RETURN
CONTEXT:  PL/pgSQL function dwh.inovus_logs()


During handling of the above exception, another exception occurred:

Traceback (most recent call last):
  File "/home/airflow/.local/lib/python3.6/site-packages/airflow/models/taskinstance.py", line 1165, in _run_raw_task
    self._prepare_and_execute_task_with_callbacks(context, task)
  File "/home/airflow/.local/lib/python3.6/site-packages/airflow/models/taskinstance.py", line 1283, in _prepare_and_execute_task_with_callbacks
    result = self._execute_task(context, task_copy)
  File "/home/airflow/.local/lib/python3.6/site-packages/airflow/models/taskinstance.py", line 1313, in _execute_task
    result = task_copy.execute(context=context)
  File "/home/airflow/.local/lib/python3.6/site-packages/airflow/operators/python.py", line 150, in execute
    return_value = self.execute_callable()
  File "/home/airflow/.local/lib/python3.6/site-packages/airflow/operators/python.py", line 161, in execute_callable
    return self.python_callable(*self.op_args, **self.op_kwargs)
  File "/opt/airflow/dags/inovus_etl_stg_dwh.py", line 51, in etl_inovus_dwh_f_sale
    raise Exception
Exception
[2023-04-02 17:30:01,832] {taskinstance.py:1513} INFO - Marking task as FAILED. dag_id=inovus_etl_dag_stg_to_dwh, task_id=etl_from_stgfsales_to_dwhfsales, execution_date=20230402T172957, start_date=20230402T173001, end_date=20230402T173001
[2023-04-02 17:30:01,883] {local_task_job.py:151} INFO - Task exited with return code 1
[2023-04-02 17:30:01,940] {local_task_job.py:261} INFO - 0 downstream tasks scheduled from follow-on schedule check
