[2023-03-30 02:07:29,188] {taskinstance.py:903} INFO - Dependencies all met for <TaskInstance: inovus_etl_dag_mrr_to_stg.etl_from_mrrfsales_to_stgfsales 2023-03-29T00:00:00+00:00 [queued]>
[2023-03-30 02:07:29,543] {taskinstance.py:903} INFO - Dependencies all met for <TaskInstance: inovus_etl_dag_mrr_to_stg.etl_from_mrrfsales_to_stgfsales 2023-03-29T00:00:00+00:00 [queued]>
[2023-03-30 02:07:29,557] {taskinstance.py:1095} INFO - 
--------------------------------------------------------------------------------
[2023-03-30 02:07:29,561] {taskinstance.py:1096} INFO - Starting attempt 1 of 1
[2023-03-30 02:07:29,566] {taskinstance.py:1097} INFO - 
--------------------------------------------------------------------------------
[2023-03-30 02:07:29,736] {taskinstance.py:1115} INFO - Executing <Task(PythonOperator): etl_from_mrrfsales_to_stgfsales> on 2023-03-29T00:00:00+00:00
[2023-03-30 02:07:30,091] {standard_task_runner.py:76} INFO - Running: ['***', 'tasks', 'run', 'inovus_etl_dag_mrr_to_stg', 'etl_from_mrrfsales_to_stgfsales', '2023-03-29T00:00:00+00:00', '--job-id', '457', '--pool', 'default_pool', '--raw', '--subdir', 'DAGS_FOLDER/inovus_etl_mrr_stg.py', '--cfg-path', '/tmp/tmpyxocdrmr', '--error-file', '/tmp/tmpgfc30cra']
[2023-03-30 02:07:30,118] {standard_task_runner.py:77} INFO - Job 457: Subtask etl_from_mrrfsales_to_stgfsales
[2023-03-30 02:07:29,957] {standard_task_runner.py:52} INFO - Started process 82 to run task
[2023-03-30 02:07:30,885] {logging_mixin.py:109} INFO - Running <TaskInstance: inovus_etl_dag_mrr_to_stg.etl_from_mrrfsales_to_stgfsales 2023-03-29T00:00:00+00:00 [running]> on host 0bc3da97cebb
[2023-03-30 02:07:31,493] {taskinstance.py:1254} INFO - Exporting the following env vars:
AIRFLOW_CTX_DAG_OWNER=***
AIRFLOW_CTX_DAG_ID=inovus_etl_dag_mrr_to_stg
AIRFLOW_CTX_TASK_ID=etl_from_mrrfsales_to_stgfsales
AIRFLOW_CTX_EXECUTION_DATE=2023-03-29T00:00:00+00:00
AIRFLOW_CTX_DAG_RUN_ID=scheduled__2023-03-29T00:00:00+00:00
[2023-03-30 02:07:31,511] {taskinstance.py:1463} ERROR - Task failed with exception
Traceback (most recent call last):
  File "/home/airflow/.local/lib/python3.6/site-packages/airflow/models/taskinstance.py", line 1165, in _run_raw_task
    self._prepare_and_execute_task_with_callbacks(context, task)
  File "/home/airflow/.local/lib/python3.6/site-packages/airflow/models/taskinstance.py", line 1283, in _prepare_and_execute_task_with_callbacks
    result = self._execute_task(context, task_copy)
  File "/home/airflow/.local/lib/python3.6/site-packages/airflow/models/taskinstance.py", line 1313, in _execute_task
    result = task_copy.execute(context=context)
  File "/home/airflow/.local/lib/python3.6/site-packages/airflow/operators/python.py", line 150, in execute
    return_value = self.execute_callable()
  File "/home/airflow/.local/lib/python3.6/site-packages/airflow/operators/python.py", line 161, in execute_callable
    return self.python_callable(*self.op_args, **self.op_kwargs)
  File "/opt/airflow/dags/inovus_etl_mrr_stg.py", line 20, in etl_inovus_fsale
    conn_inovus = get_inovus_connection() # 1
  File "/opt/airflow/dags/inovus_etl_mrr_stg.py", line 14, in get_inovus_connection
    port="5433"
  File "/home/airflow/.local/lib/python3.6/site-packages/psycopg2/__init__.py", line 122, in connect
    conn = _connect(dsn, connection_factory=connection_factory, **kwasync)
psycopg2.OperationalError: could not connect to server: Connection refused
	Is the server running on host "host.docker.internal" (192.168.65.2) and accepting
	TCP/IP connections on port 5433?

[2023-03-30 02:07:31,558] {taskinstance.py:1513} INFO - Marking task as FAILED. dag_id=inovus_etl_dag_mrr_to_stg, task_id=etl_from_mrrfsales_to_stgfsales, execution_date=20230329T000000, start_date=20230330T020729, end_date=20230330T020731
[2023-03-30 02:07:31,751] {local_task_job.py:151} INFO - Task exited with return code 1
[2023-03-30 02:07:32,147] {local_task_job.py:261} INFO - 0 downstream tasks scheduled from follow-on schedule check
