[2023-03-29 16:42:28,371] {taskinstance.py:903} INFO - Dependencies all met for <TaskInstance: postgres_22222222222.log_suc 2023-03-29T16:42:21.791298+00:00 [queued]>
[2023-03-29 16:42:28,402] {taskinstance.py:903} INFO - Dependencies all met for <TaskInstance: postgres_22222222222.log_suc 2023-03-29T16:42:21.791298+00:00 [queued]>
[2023-03-29 16:42:28,404] {taskinstance.py:1095} INFO - 
--------------------------------------------------------------------------------
[2023-03-29 16:42:28,405] {taskinstance.py:1096} INFO - Starting attempt 1 of 1
[2023-03-29 16:42:28,406] {taskinstance.py:1097} INFO - 
--------------------------------------------------------------------------------
[2023-03-29 16:42:28,424] {taskinstance.py:1115} INFO - Executing <Task(PythonOperator): log_suc> on 2023-03-29T16:42:21.791298+00:00
[2023-03-29 16:42:28,432] {standard_task_runner.py:52} INFO - Started process 27734 to run task
[2023-03-29 16:42:28,441] {standard_task_runner.py:76} INFO - Running: ['***', 'tasks', 'run', 'postgres_22222222222', 'log_suc', '2023-03-29T16:42:21.791298+00:00', '--job-id', '415', '--pool', 'default_pool', '--raw', '--subdir', 'DAGS_FOLDER/ETL.py', '--cfg-path', '/tmp/tmp_5q9uy4r', '--error-file', '/tmp/tmp655ocyng']
[2023-03-29 16:42:28,443] {standard_task_runner.py:77} INFO - Job 415: Subtask log_suc
[2023-03-29 16:42:28,502] {logging_mixin.py:109} INFO - Running <TaskInstance: postgres_22222222222.log_suc 2023-03-29T16:42:21.791298+00:00 [running]> on host 0bc3da97cebb
[2023-03-29 16:42:28,570] {taskinstance.py:1254} INFO - Exporting the following env vars:
AIRFLOW_CTX_DAG_OWNER=***
AIRFLOW_CTX_DAG_ID=postgres_22222222222
AIRFLOW_CTX_TASK_ID=log_suc
AIRFLOW_CTX_EXECUTION_DATE=2023-03-29T16:42:21.791298+00:00
AIRFLOW_CTX_DAG_RUN_ID=manual__2023-03-29T16:42:21.791298+00:00
[2023-03-29 16:42:28,573] {ETL.py:53} INFO - completed
[2023-03-29 16:42:28,595] {taskinstance.py:1463} ERROR - Task failed with exception
Traceback (most recent call last):
  File "/home/airflow/.local/lib/python3.6/site-packages/airflow/models/taskinstance.py", line 1165, in _run_raw_task
    self._prepare_and_execute_task_with_callbacks(context, task)
  File "/home/airflow/.local/lib/python3.6/site-packages/airflow/models/taskinstance.py", line 1283, in _prepare_and_execute_task_with_callbacks
    result = self._execute_task(context, task_copy)
  File "/home/airflow/.local/lib/python3.6/site-packages/airflow/models/taskinstance.py", line 1313, in _execute_task
    result = task_copy.execute(context=context)
  File "/home/airflow/.local/lib/python3.6/site-packages/airflow/operators/python.py", line 150, in execute
    return_value = self.execute_callable()
  File "/home/airflow/.local/lib/python3.6/site-packages/airflow/operators/python.py", line 161, in execute_callable
    return self.python_callable(*self.op_args, **self.op_kwargs)
  File "/opt/airflow/dags/ETL.py", line 60, in creatte_log_suc
    cur.execute('insert into logs.etl_logs (event_time, event_name, event_type) VALUES (%s, %s, %s)', (type(mes), 'value2', 'value3'))
psycopg2.ProgrammingError: can't adapt type 'type'
[2023-03-29 16:42:28,601] {taskinstance.py:1513} INFO - Marking task as FAILED. dag_id=postgres_22222222222, task_id=log_suc, execution_date=20230329T164221, start_date=20230329T164228, end_date=20230329T164228
[2023-03-29 16:42:28,655] {local_task_job.py:151} INFO - Task exited with return code 1
[2023-03-29 16:42:28,685] {local_task_job.py:261} INFO - 0 downstream tasks scheduled from follow-on schedule check
