[2023-03-28 13:55:02,308] {taskinstance.py:903} INFO - Dependencies all met for <TaskInstance: postgres_etl_dag.etl_from_radb 2023-03-28T13:55:00.142610+00:00 [queued]>
[2023-03-28 13:55:02,347] {taskinstance.py:903} INFO - Dependencies all met for <TaskInstance: postgres_etl_dag.etl_from_radb 2023-03-28T13:55:00.142610+00:00 [queued]>
[2023-03-28 13:55:02,349] {taskinstance.py:1095} INFO - 
--------------------------------------------------------------------------------
[2023-03-28 13:55:02,352] {taskinstance.py:1096} INFO - Starting attempt 1 of 1
[2023-03-28 13:55:02,355] {taskinstance.py:1097} INFO - 
--------------------------------------------------------------------------------
[2023-03-28 13:55:02,374] {taskinstance.py:1115} INFO - Executing <Task(PythonOperator): etl_from_radb> on 2023-03-28T13:55:00.142610+00:00
[2023-03-28 13:55:02,390] {standard_task_runner.py:52} INFO - Started process 3099 to run task
[2023-03-28 13:55:02,409] {standard_task_runner.py:76} INFO - Running: ['***', 'tasks', 'run', 'postgres_etl_dag', 'etl_from_radb', '2023-03-28T13:55:00.142610+00:00', '--job-id', '21', '--pool', 'default_pool', '--raw', '--subdir', 'DAGS_FOLDER/ETL.py', '--cfg-path', '/tmp/tmp7yc4rnrm', '--error-file', '/tmp/tmpv09a95l7']
[2023-03-28 13:55:02,415] {standard_task_runner.py:77} INFO - Job 21: Subtask etl_from_radb
[2023-03-28 13:55:02,487] {logging_mixin.py:109} INFO - Running <TaskInstance: postgres_etl_dag.etl_from_radb 2023-03-28T13:55:00.142610+00:00 [running]> on host 0bc3da97cebb
[2023-03-28 13:55:02,583] {taskinstance.py:1254} INFO - Exporting the following env vars:
AIRFLOW_CTX_DAG_OWNER=***
AIRFLOW_CTX_DAG_ID=postgres_etl_dag
AIRFLOW_CTX_TASK_ID=etl_from_radb
AIRFLOW_CTX_EXECUTION_DATE=2023-03-28T13:55:00.142610+00:00
AIRFLOW_CTX_DAG_RUN_ID=manual__2023-03-28T13:55:00.142610+00:00
[2023-03-28 13:55:02,973] {taskinstance.py:1463} ERROR - Task failed with exception
Traceback (most recent call last):
  File "/home/airflow/.local/lib/python3.6/site-packages/airflow/models/taskinstance.py", line 1165, in _run_raw_task
    self._prepare_and_execute_task_with_callbacks(context, task)
  File "/home/airflow/.local/lib/python3.6/site-packages/airflow/models/taskinstance.py", line 1283, in _prepare_and_execute_task_with_callbacks
    result = self._execute_task(context, task_copy)
  File "/home/airflow/.local/lib/python3.6/site-packages/airflow/models/taskinstance.py", line 1313, in _execute_task
    result = task_copy.execute(context=context)
  File "/home/airflow/.local/lib/python3.6/site-packages/airflow/operators/python.py", line 150, in execute
    return_value = self.execute_callable()
  File "/home/airflow/.local/lib/python3.6/site-packages/airflow/operators/python.py", line 161, in execute_callable
    return self.python_callable(*self.op_args, **self.op_kwargs)
  File "/opt/airflow/dags/ETL.py", line 77, in etl_postgres
    cur_i.executemany('insert into mrr.fact_sales values (%s, %s, %s)', rows) # 2
psycopg2.errors.UndefinedTable: relation "mrr.fact_sales" does not exist
LINE 1: insert into mrr.fact_sales values (111, 111, 'test')
                    ^

[2023-03-28 13:55:02,988] {taskinstance.py:1513} INFO - Marking task as FAILED. dag_id=postgres_etl_dag, task_id=etl_from_radb, execution_date=20230328T135500, start_date=20230328T135502, end_date=20230328T135502
[2023-03-28 13:55:03,077] {local_task_job.py:151} INFO - Task exited with return code 1
[2023-03-28 13:55:03,118] {local_task_job.py:261} INFO - 0 downstream tasks scheduled from follow-on schedule check
