[2023-03-29 16:21:57,959] {taskinstance.py:903} INFO - Dependencies all met for <TaskInstance: postgres_22222222222.log_suc 2023-03-29T16:21:51.925717+00:00 [queued]>
[2023-03-29 16:21:57,980] {taskinstance.py:903} INFO - Dependencies all met for <TaskInstance: postgres_22222222222.log_suc 2023-03-29T16:21:51.925717+00:00 [queued]>
[2023-03-29 16:21:57,983] {taskinstance.py:1095} INFO - 
--------------------------------------------------------------------------------
[2023-03-29 16:21:57,985] {taskinstance.py:1096} INFO - Starting attempt 1 of 1
[2023-03-29 16:21:57,986] {taskinstance.py:1097} INFO - 
--------------------------------------------------------------------------------
[2023-03-29 16:21:58,009] {taskinstance.py:1115} INFO - Executing <Task(PythonOperator): log_suc> on 2023-03-29T16:21:51.925717+00:00
[2023-03-29 16:21:58,019] {standard_task_runner.py:52} INFO - Started process 26609 to run task
[2023-03-29 16:21:58,027] {standard_task_runner.py:76} INFO - Running: ['***', 'tasks', 'run', 'postgres_22222222222', 'log_suc', '2023-03-29T16:21:51.925717+00:00', '--job-id', '325', '--pool', 'default_pool', '--raw', '--subdir', 'DAGS_FOLDER/ETL.py', '--cfg-path', '/tmp/tmpojo7mr45', '--error-file', '/tmp/tmpxvgh7ja1']
[2023-03-29 16:21:58,033] {standard_task_runner.py:77} INFO - Job 325: Subtask log_suc
[2023-03-29 16:21:58,098] {logging_mixin.py:109} INFO - Running <TaskInstance: postgres_22222222222.log_suc 2023-03-29T16:21:51.925717+00:00 [running]> on host 0bc3da97cebb
[2023-03-29 16:21:58,157] {taskinstance.py:1254} INFO - Exporting the following env vars:
AIRFLOW_CTX_DAG_OWNER=***
AIRFLOW_CTX_DAG_ID=postgres_22222222222
AIRFLOW_CTX_TASK_ID=log_suc
AIRFLOW_CTX_EXECUTION_DATE=2023-03-29T16:21:51.925717+00:00
AIRFLOW_CTX_DAG_RUN_ID=manual__2023-03-29T16:21:51.925717+00:00
[2023-03-29 16:21:58,159] {ETL.py:53} INFO - completed
[2023-03-29 16:21:58,176] {taskinstance.py:1463} ERROR - Task failed with exception
Traceback (most recent call last):
  File "/home/airflow/.local/lib/python3.6/site-packages/airflow/models/taskinstance.py", line 1165, in _run_raw_task
    self._prepare_and_execute_task_with_callbacks(context, task)
  File "/home/airflow/.local/lib/python3.6/site-packages/airflow/models/taskinstance.py", line 1283, in _prepare_and_execute_task_with_callbacks
    result = self._execute_task(context, task_copy)
  File "/home/airflow/.local/lib/python3.6/site-packages/airflow/models/taskinstance.py", line 1313, in _execute_task
    result = task_copy.execute(context=context)
  File "/home/airflow/.local/lib/python3.6/site-packages/airflow/operators/python.py", line 150, in execute
    return_value = self.execute_callable()
  File "/home/airflow/.local/lib/python3.6/site-packages/airflow/operators/python.py", line 161, in execute_callable
    return self.python_callable(*self.op_args, **self.op_kwargs)
  File "/opt/airflow/dags/ETL.py", line 60, in creatte_log_suc
    cur.executemany("insert into logs.etl_logs (event_time, event_name, event_type) VALUES (%s, %s, %s)", ("value1", "value2", "value3"))
TypeError: not all arguments converted during string formatting
[2023-03-29 16:21:58,181] {taskinstance.py:1513} INFO - Marking task as FAILED. dag_id=postgres_22222222222, task_id=log_suc, execution_date=20230329T162151, start_date=20230329T162157, end_date=20230329T162158
[2023-03-29 16:21:58,246] {local_task_job.py:151} INFO - Task exited with return code 1
[2023-03-29 16:21:58,285] {local_task_job.py:261} INFO - 0 downstream tasks scheduled from follow-on schedule check
