[2023-03-31 00:09:09,680] {taskinstance.py:903} INFO - Dependencies all met for <TaskInstance: inovus_etl_dag_stg_to_dwh.etl_from_stgdimcustomer_to_dwhdimcustomer 2023-03-30T00:00:00+00:00 [queued]>
[2023-03-31 00:09:09,816] {taskinstance.py:903} INFO - Dependencies all met for <TaskInstance: inovus_etl_dag_stg_to_dwh.etl_from_stgdimcustomer_to_dwhdimcustomer 2023-03-30T00:00:00+00:00 [queued]>
[2023-03-31 00:09:09,824] {taskinstance.py:1095} INFO - 
--------------------------------------------------------------------------------
[2023-03-31 00:09:09,827] {taskinstance.py:1096} INFO - Starting attempt 1 of 1
[2023-03-31 00:09:09,828] {taskinstance.py:1097} INFO - 
--------------------------------------------------------------------------------
[2023-03-31 00:09:09,906] {taskinstance.py:1115} INFO - Executing <Task(PythonOperator): etl_from_stgdimcustomer_to_dwhdimcustomer> on 2023-03-30T00:00:00+00:00
[2023-03-31 00:09:09,978] {standard_task_runner.py:52} INFO - Started process 1435 to run task
[2023-03-31 00:09:10,057] {standard_task_runner.py:76} INFO - Running: ['***', 'tasks', 'run', 'inovus_etl_dag_stg_to_dwh', 'etl_from_stgdimcustomer_to_dwhdimcustomer', '2023-03-30T00:00:00+00:00', '--job-id', '496', '--pool', 'default_pool', '--raw', '--subdir', 'DAGS_FOLDER/inovus_etl_stg_dwh.py', '--cfg-path', '/tmp/tmp4yf8m1r6', '--error-file', '/tmp/tmpxzbsz6wj']
[2023-03-31 00:09:10,069] {standard_task_runner.py:77} INFO - Job 496: Subtask etl_from_stgdimcustomer_to_dwhdimcustomer
[2023-03-31 00:09:10,859] {logging_mixin.py:109} INFO - Running <TaskInstance: inovus_etl_dag_stg_to_dwh.etl_from_stgdimcustomer_to_dwhdimcustomer 2023-03-30T00:00:00+00:00 [running]> on host 0bc3da97cebb
[2023-03-31 00:09:11,354] {taskinstance.py:1254} INFO - Exporting the following env vars:
AIRFLOW_CTX_DAG_OWNER=***
AIRFLOW_CTX_DAG_ID=inovus_etl_dag_stg_to_dwh
AIRFLOW_CTX_TASK_ID=etl_from_stgdimcustomer_to_dwhdimcustomer
AIRFLOW_CTX_EXECUTION_DATE=2023-03-30T00:00:00+00:00
AIRFLOW_CTX_DAG_RUN_ID=scheduled__2023-03-30T00:00:00+00:00
[2023-03-31 00:09:11,836] {taskinstance.py:1463} ERROR - Task failed with exception
Traceback (most recent call last):
  File "/opt/airflow/dags/inovus_etl_stg_dwh.py", line 62, in etl_inovus_dwh_dimcustomer
    cur.executemany('insert into dwh.dimension_customer values (%s, %s, %s)', rows) # 2
psycopg2.errors.UniqueViolation: duplicate key value violates unique constraint "pk_1"
DETAIL:  Key (id)=(1) already exists.


During handling of the above exception, another exception occurred:

Traceback (most recent call last):
  File "/home/airflow/.local/lib/python3.6/site-packages/airflow/models/taskinstance.py", line 1165, in _run_raw_task
    self._prepare_and_execute_task_with_callbacks(context, task)
  File "/home/airflow/.local/lib/python3.6/site-packages/airflow/models/taskinstance.py", line 1283, in _prepare_and_execute_task_with_callbacks
    result = self._execute_task(context, task_copy)
  File "/home/airflow/.local/lib/python3.6/site-packages/airflow/models/taskinstance.py", line 1313, in _execute_task
    result = task_copy.execute(context=context)
  File "/home/airflow/.local/lib/python3.6/site-packages/airflow/operators/python.py", line 150, in execute
    return_value = self.execute_callable()
  File "/home/airflow/.local/lib/python3.6/site-packages/airflow/operators/python.py", line 161, in execute_callable
    return self.python_callable(*self.op_args, **self.op_kwargs)
  File "/opt/airflow/dags/inovus_etl_stg_dwh.py", line 66, in etl_inovus_dwh_dimcustomer
    raise Exception
Exception
[2023-03-31 00:09:12,015] {taskinstance.py:1513} INFO - Marking task as FAILED. dag_id=inovus_etl_dag_stg_to_dwh, task_id=etl_from_stgdimcustomer_to_dwhdimcustomer, execution_date=20230330T000000, start_date=20230331T000909, end_date=20230331T000911
[2023-03-31 00:09:12,858] {local_task_job.py:151} INFO - Task exited with return code 1
[2023-03-31 00:09:13,113] {local_task_job.py:261} INFO - 0 downstream tasks scheduled from follow-on schedule check
