[2023-03-30 03:26:40,154] {taskinstance.py:903} INFO - Dependencies all met for <TaskInstance: postgres_22222222222.etl_from_radb_to_mrrfsales 2023-03-30T03:26:36.605884+00:00 [queued]>
[2023-03-30 03:26:40,178] {taskinstance.py:903} INFO - Dependencies all met for <TaskInstance: postgres_22222222222.etl_from_radb_to_mrrfsales 2023-03-30T03:26:36.605884+00:00 [queued]>
[2023-03-30 03:26:40,179] {taskinstance.py:1095} INFO - 
--------------------------------------------------------------------------------
[2023-03-30 03:26:40,180] {taskinstance.py:1096} INFO - Starting attempt 1 of 1
[2023-03-30 03:26:40,182] {taskinstance.py:1097} INFO - 
--------------------------------------------------------------------------------
[2023-03-30 03:26:40,194] {taskinstance.py:1115} INFO - Executing <Task(PythonOperator): etl_from_radb_to_mrrfsales> on 2023-03-30T03:26:36.605884+00:00
[2023-03-30 03:26:40,200] {standard_task_runner.py:52} INFO - Started process 3712 to run task
[2023-03-30 03:26:40,207] {standard_task_runner.py:76} INFO - Running: ['***', 'tasks', 'run', 'postgres_22222222222', 'etl_from_radb_to_mrrfsales', '2023-03-30T03:26:36.605884+00:00', '--job-id', '459', '--pool', 'default_pool', '--raw', '--subdir', 'DAGS_FOLDER/ETL.py', '--cfg-path', '/tmp/tmp_nw1rrg8', '--error-file', '/tmp/tmphgksniy4']
[2023-03-30 03:26:40,210] {standard_task_runner.py:77} INFO - Job 459: Subtask etl_from_radb_to_mrrfsales
[2023-03-30 03:26:40,293] {logging_mixin.py:109} INFO - Running <TaskInstance: postgres_22222222222.etl_from_radb_to_mrrfsales 2023-03-30T03:26:36.605884+00:00 [running]> on host 0bc3da97cebb
[2023-03-30 03:26:40,376] {taskinstance.py:1254} INFO - Exporting the following env vars:
AIRFLOW_CTX_DAG_OWNER=***
AIRFLOW_CTX_DAG_ID=postgres_22222222222
AIRFLOW_CTX_TASK_ID=etl_from_radb_to_mrrfsales
AIRFLOW_CTX_EXECUTION_DATE=2023-03-30T03:26:36.605884+00:00
AIRFLOW_CTX_DAG_RUN_ID=manual__2023-03-30T03:26:36.605884+00:00
[2023-03-30 03:26:40,717] {taskinstance.py:1463} ERROR - Task failed with exception
Traceback (most recent call last):
  File "/home/airflow/.local/lib/python3.6/site-packages/airflow/models/taskinstance.py", line 1165, in _run_raw_task
    self._prepare_and_execute_task_with_callbacks(context, task)
  File "/home/airflow/.local/lib/python3.6/site-packages/airflow/models/taskinstance.py", line 1283, in _prepare_and_execute_task_with_callbacks
    result = self._execute_task(context, task_copy)
  File "/home/airflow/.local/lib/python3.6/site-packages/airflow/models/taskinstance.py", line 1313, in _execute_task
    result = task_copy.execute(context=context)
  File "/home/airflow/.local/lib/python3.6/site-packages/airflow/operators/python.py", line 150, in execute
    return_value = self.execute_callable()
  File "/home/airflow/.local/lib/python3.6/site-packages/airflow/operators/python.py", line 161, in execute_callable
    return self.python_callable(*self.op_args, **self.op_kwargs)
  File "/opt/airflow/dags/ETL.py", line 60, in etl_postgres_mmr_fsale
    conn_inovus = get_postgres_i_connection() # 2
  File "/opt/airflow/dags/ETL.py", line 37, in get_postgres_i_connection
    port="5433"
  File "/home/airflow/.local/lib/python3.6/site-packages/psycopg2/__init__.py", line 122, in connect
    conn = _connect(dsn, connection_factory=connection_factory, **kwasync)
psycopg2.OperationalError: could not connect to server: Connection refused
	Is the server running on host "host.docker.internal" (192.168.65.2) and accepting
	TCP/IP connections on port 5433?

[2023-03-30 03:26:40,743] {taskinstance.py:1513} INFO - Marking task as FAILED. dag_id=postgres_22222222222, task_id=etl_from_radb_to_mrrfsales, execution_date=20230330T032636, start_date=20230330T032640, end_date=20230330T032640
[2023-03-30 03:26:40,797] {local_task_job.py:151} INFO - Task exited with return code 1
[2023-03-30 03:26:40,902] {local_task_job.py:261} INFO - 0 downstream tasks scheduled from follow-on schedule check
