[2023-03-28 18:38:58,487] {taskinstance.py:903} INFO - Dependencies all met for <TaskInstance: inovus_etl_dag_stg_to_dwh.etl_from_stgdimcustomer_to_dwhdimcustomer 2023-03-28T18:38:56.994241+00:00 [queued]>
[2023-03-28 18:38:58,524] {taskinstance.py:903} INFO - Dependencies all met for <TaskInstance: inovus_etl_dag_stg_to_dwh.etl_from_stgdimcustomer_to_dwhdimcustomer 2023-03-28T18:38:56.994241+00:00 [queued]>
[2023-03-28 18:38:58,525] {taskinstance.py:1095} INFO - 
--------------------------------------------------------------------------------
[2023-03-28 18:38:58,527] {taskinstance.py:1096} INFO - Starting attempt 1 of 1
[2023-03-28 18:38:58,528] {taskinstance.py:1097} INFO - 
--------------------------------------------------------------------------------
[2023-03-28 18:38:58,538] {taskinstance.py:1115} INFO - Executing <Task(PythonOperator): etl_from_stgdimcustomer_to_dwhdimcustomer> on 2023-03-28T18:38:56.994241+00:00
[2023-03-28 18:38:58,553] {standard_task_runner.py:76} INFO - Running: ['***', 'tasks', 'run', 'inovus_etl_dag_stg_to_dwh', 'etl_from_stgdimcustomer_to_dwhdimcustomer', '2023-03-28T18:38:56.994241+00:00', '--job-id', '71', '--pool', 'default_pool', '--raw', '--subdir', 'DAGS_FOLDER/inovus_etl_stg_dwh.py', '--cfg-path', '/tmp/tmp6bjf4ux3', '--error-file', '/tmp/tmpju26m1w7']
[2023-03-28 18:38:58,547] {standard_task_runner.py:52} INFO - Started process 9268 to run task
[2023-03-28 18:38:58,556] {standard_task_runner.py:77} INFO - Job 71: Subtask etl_from_stgdimcustomer_to_dwhdimcustomer
[2023-03-28 18:38:58,617] {logging_mixin.py:109} INFO - Running <TaskInstance: inovus_etl_dag_stg_to_dwh.etl_from_stgdimcustomer_to_dwhdimcustomer 2023-03-28T18:38:56.994241+00:00 [running]> on host 0bc3da97cebb
[2023-03-28 18:38:58,682] {taskinstance.py:1254} INFO - Exporting the following env vars:
AIRFLOW_CTX_DAG_OWNER=***
AIRFLOW_CTX_DAG_ID=inovus_etl_dag_stg_to_dwh
AIRFLOW_CTX_TASK_ID=etl_from_stgdimcustomer_to_dwhdimcustomer
AIRFLOW_CTX_EXECUTION_DATE=2023-03-28T18:38:56.994241+00:00
AIRFLOW_CTX_DAG_RUN_ID=manual__2023-03-28T18:38:56.994241+00:00
[2023-03-28 18:38:58,727] {taskinstance.py:1463} ERROR - Task failed with exception
Traceback (most recent call last):
  File "/home/airflow/.local/lib/python3.6/site-packages/airflow/models/taskinstance.py", line 1165, in _run_raw_task
    self._prepare_and_execute_task_with_callbacks(context, task)
  File "/home/airflow/.local/lib/python3.6/site-packages/airflow/models/taskinstance.py", line 1283, in _prepare_and_execute_task_with_callbacks
    result = self._execute_task(context, task_copy)
  File "/home/airflow/.local/lib/python3.6/site-packages/airflow/models/taskinstance.py", line 1313, in _execute_task
    result = task_copy.execute(context=context)
  File "/home/airflow/.local/lib/python3.6/site-packages/airflow/operators/python.py", line 150, in execute
    return_value = self.execute_callable()
  File "/home/airflow/.local/lib/python3.6/site-packages/airflow/operators/python.py", line 161, in execute_callable
    return self.python_callable(*self.op_args, **self.op_kwargs)
  File "/opt/airflow/dags/inovus_etl_stg_dwh.py", line 33, in etl_inovus_dimcustomer
    cur.executemany('insert into dwh.dimension_customer values (%s, %s, %s)', rows) # 2
psycopg2.errors.UndefinedTable: relation "dwh.dimension_customer" does not exist
LINE 1: insert into dwh.dimension_customer values (111, '111', 'test...
                    ^

[2023-03-28 18:38:58,735] {taskinstance.py:1513} INFO - Marking task as FAILED. dag_id=inovus_etl_dag_stg_to_dwh, task_id=etl_from_stgdimcustomer_to_dwhdimcustomer, execution_date=20230328T183856, start_date=20230328T183858, end_date=20230328T183858
[2023-03-28 18:38:58,777] {local_task_job.py:151} INFO - Task exited with return code 1
[2023-03-28 18:38:58,819] {local_task_job.py:261} INFO - 0 downstream tasks scheduled from follow-on schedule check
