[2023-04-02 17:10:13,169] {taskinstance.py:903} INFO - Dependencies all met for <TaskInstance: inovus_etl_dag_stg_to_dwh.etl_from_stgdimcustomer_to_dwhdimcustomer 2023-03-31T00:00:00+00:00 [queued]>
[2023-04-02 17:10:15,894] {taskinstance.py:903} INFO - Dependencies all met for <TaskInstance: inovus_etl_dag_stg_to_dwh.etl_from_stgdimcustomer_to_dwhdimcustomer 2023-03-31T00:00:00+00:00 [queued]>
[2023-04-02 17:10:15,916] {taskinstance.py:1095} INFO - 
--------------------------------------------------------------------------------
[2023-04-02 17:10:15,927] {taskinstance.py:1096} INFO - Starting attempt 1 of 1
[2023-04-02 17:10:15,953] {taskinstance.py:1097} INFO - 
--------------------------------------------------------------------------------
[2023-04-02 17:10:17,006] {taskinstance.py:1115} INFO - Executing <Task(PythonOperator): etl_from_stgdimcustomer_to_dwhdimcustomer> on 2023-03-31T00:00:00+00:00
[2023-04-02 17:10:17,311] {standard_task_runner.py:52} INFO - Started process 112 to run task
[2023-04-02 17:10:18,440] {standard_task_runner.py:76} INFO - Running: ['***', 'tasks', 'run', 'inovus_etl_dag_stg_to_dwh', 'etl_from_stgdimcustomer_to_dwhdimcustomer', '2023-03-31T00:00:00+00:00', '--job-id', '527', '--pool', 'default_pool', '--raw', '--subdir', 'DAGS_FOLDER/inovus_etl_stg_dwh.py', '--cfg-path', '/tmp/tmpzchk7wiu', '--error-file', '/tmp/tmpq7z894n2']
[2023-04-02 17:10:18,627] {standard_task_runner.py:77} INFO - Job 527: Subtask etl_from_stgdimcustomer_to_dwhdimcustomer
[2023-04-02 17:10:22,365] {logging_mixin.py:109} INFO - Running <TaskInstance: inovus_etl_dag_stg_to_dwh.etl_from_stgdimcustomer_to_dwhdimcustomer 2023-03-31T00:00:00+00:00 [running]> on host 580553a30a83
[2023-04-02 17:10:26,187] {taskinstance.py:1254} INFO - Exporting the following env vars:
AIRFLOW_CTX_DAG_OWNER=***
AIRFLOW_CTX_DAG_ID=inovus_etl_dag_stg_to_dwh
AIRFLOW_CTX_TASK_ID=etl_from_stgdimcustomer_to_dwhdimcustomer
AIRFLOW_CTX_EXECUTION_DATE=2023-03-31T00:00:00+00:00
AIRFLOW_CTX_DAG_RUN_ID=scheduled__2023-03-31T00:00:00+00:00
[2023-04-02 17:10:28,925] {taskinstance.py:1463} ERROR - Task failed with exception
Traceback (most recent call last):
  File "/opt/airflow/dags/inovus_etl_stg_dwh.py", line 62, in etl_inovus_dwh_dimcustomer
    cur.executemany('insert into dwh.dimension_customer values (%s, %s, %s)', rows) # 2
psycopg2.errors.UniqueViolation: duplicate key value violates unique constraint "pk_1"
DETAIL:  Key (id)=(1) already exists.


During handling of the above exception, another exception occurred:

Traceback (most recent call last):
  File "/home/airflow/.local/lib/python3.6/site-packages/airflow/models/taskinstance.py", line 1165, in _run_raw_task
    self._prepare_and_execute_task_with_callbacks(context, task)
  File "/home/airflow/.local/lib/python3.6/site-packages/airflow/models/taskinstance.py", line 1283, in _prepare_and_execute_task_with_callbacks
    result = self._execute_task(context, task_copy)
  File "/home/airflow/.local/lib/python3.6/site-packages/airflow/models/taskinstance.py", line 1313, in _execute_task
    result = task_copy.execute(context=context)
  File "/home/airflow/.local/lib/python3.6/site-packages/airflow/operators/python.py", line 150, in execute
    return_value = self.execute_callable()
  File "/home/airflow/.local/lib/python3.6/site-packages/airflow/operators/python.py", line 161, in execute_callable
    return self.python_callable(*self.op_args, **self.op_kwargs)
  File "/opt/airflow/dags/inovus_etl_stg_dwh.py", line 66, in etl_inovus_dwh_dimcustomer
    raise Exception
Exception
[2023-04-02 17:10:29,407] {taskinstance.py:1513} INFO - Marking task as FAILED. dag_id=inovus_etl_dag_stg_to_dwh, task_id=etl_from_stgdimcustomer_to_dwhdimcustomer, execution_date=20230331T000000, start_date=20230402T171013, end_date=20230402T171029
[2023-04-02 17:10:30,330] {local_task_job.py:151} INFO - Task exited with return code 1
[2023-04-02 17:10:31,479] {local_task_job.py:261} INFO - 0 downstream tasks scheduled from follow-on schedule check
